Traceback (most recent call last):
  File "/Users/kamiltagowski/anaconda3/envs/pdiow/lib/python3.8/site-packages/jupyter_cache/executors/utils.py", line 51, in single_nb_execution
    executenb(
  File "/Users/kamiltagowski/anaconda3/envs/pdiow/lib/python3.8/site-packages/nbclient/client.py", line 1087, in execute
    return NotebookClient(nb=nb, resources=resources, km=km, **kwargs).execute()
  File "/Users/kamiltagowski/anaconda3/envs/pdiow/lib/python3.8/site-packages/nbclient/util.py", line 74, in wrapped
    return just_run(coro(*args, **kwargs))
  File "/Users/kamiltagowski/anaconda3/envs/pdiow/lib/python3.8/site-packages/nbclient/util.py", line 53, in just_run
    return loop.run_until_complete(coro)
  File "/Users/kamiltagowski/anaconda3/envs/pdiow/lib/python3.8/asyncio/base_events.py", line 616, in run_until_complete
    return future.result()
  File "/Users/kamiltagowski/anaconda3/envs/pdiow/lib/python3.8/site-packages/nbclient/client.py", line 540, in async_execute
    await self.async_execute_cell(
  File "/Users/kamiltagowski/anaconda3/envs/pdiow/lib/python3.8/site-packages/nbclient/client.py", line 832, in async_execute_cell
    self._check_raise_for_error(cell, exec_reply)
  File "/Users/kamiltagowski/anaconda3/envs/pdiow/lib/python3.8/site-packages/nbclient/client.py", line 740, in _check_raise_for_error
    raise CellExecutionError.from_cell_and_msg(cell, exec_reply['content'])
nbclient.exceptions.CellExecutionError: An error occurred while executing the following cell:
------------------
import pandas as pd
from sklearn.datasets import load_boston

df = pd.DataFrame(dataset['data'], columns=dataset['feature_names'])
df.head()
------------------

[0;31m---------------------------------------------------------------------------[0m
[0;31mNameError[0m                                 Traceback (most recent call last)
[0;32m<ipython-input-1-5e7881ff40ac>[0m in [0;36m<module>[0;34m[0m
[1;32m      2[0m [0;32mfrom[0m [0msklearn[0m[0;34m.[0m[0mdatasets[0m [0;32mimport[0m [0mload_boston[0m[0;34m[0m[0;34m[0m[0m
[1;32m      3[0m [0;34m[0m[0m
[0;32m----> 4[0;31m [0mdf[0m [0;34m=[0m [0mpd[0m[0;34m.[0m[0mDataFrame[0m[0;34m([0m[0mdataset[0m[0;34m[[0m[0;34m'data'[0m[0;34m][0m[0;34m,[0m [0mcolumns[0m[0;34m=[0m[0mdataset[0m[0;34m[[0m[0;34m'feature_names'[0m[0;34m][0m[0;34m)[0m[0;34m[0m[0;34m[0m[0m
[0m[1;32m      5[0m [0mdf[0m[0;34m.[0m[0mhead[0m[0;34m([0m[0;34m)[0m[0;34m[0m[0;34m[0m[0m

[0;31mNameError[0m: name 'dataset' is not defined
NameError: name 'dataset' is not defined

